{"trial_id": "0001", "hyperparameters": {"space": [{"class_name": "Int", "config": {"name": "time_steps", "default": null, "conditions": [], "min_value": 10, "max_value": 100, "step": 10, "sampling": "linear"}}, {"class_name": "Int", "config": {"name": "units_layer1", "default": null, "conditions": [], "min_value": 32, "max_value": 128, "step": 32, "sampling": "linear"}}, {"class_name": "Int", "config": {"name": "units_layer2", "default": null, "conditions": [], "min_value": 16, "max_value": 64, "step": 16, "sampling": "linear"}}, {"class_name": "Boolean", "config": {"name": "use_third_lstm", "default": false, "conditions": []}}, {"class_name": "Choice", "config": {"name": "learning_rate", "default": 0.01, "conditions": [], "values": [0.01, 0.001, 0.0001], "ordered": true}}, {"class_name": "Int", "config": {"name": "units_layer3", "default": null, "conditions": [], "min_value": 16, "max_value": 64, "step": 16, "sampling": "linear"}}], "values": {"time_steps": 50, "units_layer1": 96, "units_layer2": 32, "use_third_lstm": true, "learning_rate": 0.0001, "units_layer3": 16, "tuner/epochs": 2, "tuner/initial_epoch": 0, "tuner/bracket": 3, "tuner/round": 0}}, "metrics": {"metrics": {}}, "score": null, "best_step": 0, "status": "FAILED", "message": "Traceback (most recent call last):\n  File \"c:\\Users\\Chappyyyyyy\\anaconda3\\envs\\keras\\lib\\site-packages\\keras_tuner\\src\\engine\\base_tuner.py\", line 274, in _try_run_and_update_trial\n    self._run_and_update_trial(trial, *fit_args, **fit_kwargs)\n  File \"c:\\Users\\Chappyyyyyy\\anaconda3\\envs\\keras\\lib\\site-packages\\keras_tuner\\src\\engine\\base_tuner.py\", line 239, in _run_and_update_trial\n    results = self.run_trial(trial, *fit_args, **fit_kwargs)\n  File \"c:\\Users\\Chappyyyyyy\\anaconda3\\envs\\keras\\lib\\site-packages\\keras_tuner\\src\\tuners\\hyperband.py\", line 427, in run_trial\n    return super().run_trial(trial, *fit_args, **fit_kwargs)\n  File \"c:\\Users\\Chappyyyyyy\\anaconda3\\envs\\keras\\lib\\site-packages\\keras_tuner\\src\\engine\\tuner.py\", line 314, in run_trial\n    obj_value = self._build_and_fit_model(trial, *args, **copied_kwargs)\n  File \"c:\\Users\\Chappyyyyyy\\anaconda3\\envs\\keras\\lib\\site-packages\\keras_tuner\\src\\engine\\tuner.py\", line 233, in _build_and_fit_model\n    results = self.hypermodel.fit(hp, model, *args, **kwargs)\n  File \"c:\\Users\\Chappyyyyyy\\anaconda3\\envs\\keras\\lib\\site-packages\\keras_tuner\\src\\engine\\hypermodel.py\", line 149, in fit\n    return model.fit(*args, **kwargs)\n  File \"c:\\Users\\Chappyyyyyy\\anaconda3\\envs\\keras\\lib\\site-packages\\keras\\utils\\traceback_utils.py\", line 70, in error_handler\n    raise e.with_traceback(filtered_tb) from None\n  File \"C:\\Users\\CHAPPY~1\\AppData\\Local\\Temp\\__autograph_generated_filevnbs1gpi.py\", line 15, in tf__train_function\n    retval_ = ag__.converted_call(ag__.ld(step_function), (ag__.ld(self), ag__.ld(iterator)), None, fscope)\nValueError: in user code:\n\n    File \"c:\\Users\\Chappyyyyyy\\anaconda3\\envs\\keras\\lib\\site-packages\\keras\\engine\\training.py\", line 1160, in train_function  *\n        return step_function(self, iterator)\n    File \"c:\\Users\\Chappyyyyyy\\anaconda3\\envs\\keras\\lib\\site-packages\\keras\\engine\\training.py\", line 1146, in step_function  **\n        outputs = model.distribute_strategy.run(run_step, args=(data,))\n    File \"c:\\Users\\Chappyyyyyy\\anaconda3\\envs\\keras\\lib\\site-packages\\keras\\engine\\training.py\", line 1135, in run_step  **\n        outputs = model.train_step(data)\n    File \"c:\\Users\\Chappyyyyyy\\anaconda3\\envs\\keras\\lib\\site-packages\\keras\\engine\\training.py\", line 993, in train_step\n        y_pred = self(x, training=True)\n    File \"c:\\Users\\Chappyyyyyy\\anaconda3\\envs\\keras\\lib\\site-packages\\keras\\utils\\traceback_utils.py\", line 70, in error_handler\n        raise e.with_traceback(filtered_tb) from None\n    File \"c:\\Users\\Chappyyyyyy\\anaconda3\\envs\\keras\\lib\\site-packages\\keras\\engine\\input_spec.py\", line 295, in assert_input_compatibility\n        raise ValueError(\n\n    ValueError: Input 0 of layer \"sequential\" is incompatible with the layer: expected shape=(None, 50, 12), found shape=(None, 30, 12)\n\n"}